<?xml version="1.0"?>
<robot xmlns:xacro="http://www.ros.org/wiki/xacro" xmlns:controller="http://playerstage.sourceforge.net/gazebo/xmlschema/#controller">
	<macro name="wrist_link" params="parent_link">
		<link name="FourthLink">
			<inertial>
				<origin xyz="-0.000129381758547355 0.0430627866930996 0.150035156293387" rpy="0 0 0" />
				<mass value="0.017270635973466" />
				<inertia ixx="0.0144861530368099" ixy="-7.35011796438337E-08" ixz="1.46278041404691E-05" iyy="0.0143994232215456" iyz="-0.000349637115920233" izz="0.00465327086275674" />
			</inertial>
			<visual>
				<origin xyz="0 0 0" rpy="0 0 ${pi/2}" />
				<geometry>
					<mesh filename="package://wam_description/meshes/wam7dof_link4.STL" />
				</geometry>
				<material name="">
					<color rgba="0.666666666666667 0.63921568627451 0.556862745098039 1" />
				</material>
			</visual>
			<collision>
				<origin xyz="0 0 0" rpy="0 0 ${pi/2}" />
				<geometry>
					<mesh filename="package://wam_description/meshes/wam7dof_link4.STL" />
				</geometry>
			</collision>
		</link>
		<joint name="q4" type="revolute">
			<origin xyz="0.045 0 0" rpy="${pi/2} 0 0" />
			<parent link="${parent_link}" />
			<child link="FourthLink" />
			<axis xyz="0 1 0" />
			<limit lower="-0.9" upper="3.1" effort="40" velocity="10" />
		</joint>
		<link name="FifthLink">
			<inertial>
				<origin xyz="6.78196069913216E-14 0.0187615886070163 -1.8990032765365E-08" rpy="0 0 0" />
				<mass value="0.0149005443008753" />
				<inertia ixx="8.68246260680858E-05" ixy="8.32563149485477E-12" ixz="9.56774172507725E-11" iyy="8.70844273808338E-05" iyz="8.15648112659227E-11" izz="6.71124003197135E-05" />
			</inertial>
			<visual>
				<origin xyz="0 0.022 0" rpy="${pi} -${pi/2} 0" />
				<geometry>
					<mesh filename="package://wam_description/meshes/wam7dof_link5.STL" />
				</geometry>
				<material name="">
					<color rgba="0.47843137254902 0.454901960784314 0.345098039215686 1" />
				</material>
			</visual>
			<collision>
				<origin xyz="0 -0.05 0" rpy="0 0 0" />
				<geometry>
					<mesh filename="package://wam_description/meshes/wam7dof_link5.STL" />
				</geometry>
			</collision>
		</link>
		<joint name="q5" type="revolute">
			<origin xyz="-0.045 0 0.3" rpy="-${pi/2} 0 0" />
			<parent link="FourthLink" />
			<child link="FifthLink" />
			<axis xyz="0 1 0" />
			<limit lower="-4.76" upper="1.24" effort="40" velocity="10" />
		</joint>
		<link name="SixthLink">
			<inertial>
				<origin xyz="-0.0139658979390116 0.0242366974396766 9.86247031466266E-08" rpy="0 0 0" />
				<mass value="0.000506696185792322" />
				<inertia ixx="0.000369379806854581" ixy="1.50400439239954E-05" ixz="-2.41001577391907E-09" iyy="0.000619056939139963" iyz="1.91499423781416E-10" izz="0.000747159541140852" />
			</inertial>
			<visual>
				<origin xyz="0 0.0075 0" rpy="${pi/2} 0 ${pi/2}" />
				<geometry>
					<mesh filename="package://wam_description/meshes/wam7dof_link6.STL" />
				</geometry>
				<material name="">
					<color rgba="0.898039215686275 0.917647058823529 0.929411764705882 1" />
				</material>
			</visual>
			<collision>
				<origin xyz="0 0 0" rpy="0 0 0" />
				<geometry>
					<mesh filename="package://wam_description/meshes/wam7dof_link6.STL" />
				</geometry>
			</collision>
		</link>
		<joint name="q6" type="revolute">
			<origin xyz="0 0 0" rpy="${pi/2} 0 0" />
			<parent link="FifthLink" />
			<child link="SixthLink" />
			<axis xyz="0 1 0" />
			<dynamics damping="50.0" friction="30" />
			<limit lower="-1.6" upper="1.6" effort="40" velocity="10" />
		</joint>
		<link name="SeventhLink">
			<inertial>
				<origin xyz="-2.76116528402228E-16 0.00888734044750605 1.73472347597681E-18" rpy="0 0 0" />
				<mass value="0.0991011928366143" />
				<inertia ixx="6.46940974881037E-05" ixy="-7.72224623395982E-21" ixz="-3.76158192263132E-36" iyy="0.000127725203661566" iyz="2.6027372930156E-21" izz="6.46940974881037E-05" />
			</inertial>
			<visual>
				<origin xyz="0.0001 0.000097 -0.01" rpy="${pi/2} 0 0" />
				<geometry>
					<mesh filename="package://wam_description/meshes/wam7dof_link7.STL" />
				</geometry>
				<material name="">
					<color rgba="0.831372549019608 0.847058823529412 0.858823529411765 1" />
				</material>
			</visual>
			<collision>
				<origin xyz="0 0 0" rpy="0 0 0" />
				<geometry>
					<mesh filename="package://wam_description/meshes/wam7dof_link7.STL" />
				</geometry>
			</collision>
		</link>
		<joint name="q7" type="revolute">
			<origin xyz="0 0 0.06" rpy="0 0 0" />
			<parent link="SixthLink" />
			<child link="SeventhLink" />
			<axis xyz="0 0 1" />
			<limit lower="-3" upper="3" effort="40" velocity="10" />
		</joint>
	</macro>
</robot>
